Traceback (most recent call last):
  File "/Users/puneetg/miniforge3/envs/meta/lib/python3.9/site-packages/jupyter_cache/executors/utils.py", line 51, in single_nb_execution
    executenb(
  File "/Users/puneetg/miniforge3/envs/meta/lib/python3.9/site-packages/nbclient/client.py", line 1204, in execute
    return NotebookClient(nb=nb, resources=resources, km=km, **kwargs).execute()
  File "/Users/puneetg/miniforge3/envs/meta/lib/python3.9/site-packages/nbclient/util.py", line 84, in wrapped
    return just_run(coro(*args, **kwargs))
  File "/Users/puneetg/miniforge3/envs/meta/lib/python3.9/site-packages/nbclient/util.py", line 62, in just_run
    return loop.run_until_complete(coro)
  File "/Users/puneetg/miniforge3/envs/meta/lib/python3.9/asyncio/base_events.py", line 647, in run_until_complete
    return future.result()
  File "/Users/puneetg/miniforge3/envs/meta/lib/python3.9/site-packages/nbclient/client.py", line 663, in async_execute
    await self.async_execute_cell(
  File "/Users/puneetg/miniforge3/envs/meta/lib/python3.9/site-packages/nbclient/client.py", line 965, in async_execute_cell
    await self._check_raise_for_error(cell, cell_index, exec_reply)
  File "/Users/puneetg/miniforge3/envs/meta/lib/python3.9/site-packages/nbclient/client.py", line 862, in _check_raise_for_error
    raise CellExecutionError.from_cell_and_msg(cell, exec_reply_content)
nbclient.exceptions.CellExecutionError: An error occurred while executing the following cell:
------------------
n_atoms = 51
v_max = 10
v_min = -10

q_func = q_functions.DistributionalFCStateQFunctionWithDiscreteAction(
        obs_size,
        n_actions,
        n_atoms,
        v_min,
        v_max,
        n_hidden_channels=args.n_hidden_channels,
        n_hidden_layers=args.n_hidden_layers,
)print(q_func)
------------------

[0;36m  Input [0;32mIn [11][0;36m[0m
[0;31m    )print(q_func)[0m
[0m     ^[0m
[0;31mSyntaxError[0m[0;31m:[0m invalid syntax

SyntaxError: invalid syntax (3169043061.py, line 13)

